Internal Server Error: /categories/category/create/
Traceback (most recent call last):
  File "/home/kesley/Documents/house-management/backend/venv/lib/python3.11/site-packages/django/core/handlers/exception.py", line 55, in inner
    response = get_response(request)
               ^^^^^^^^^^^^^^^^^^^^^
  File "/home/kesley/Documents/house-management/backend/venv/lib/python3.11/site-packages/django/core/handlers/base.py", line 197, in _get_response
    response = wrapped_callback(request, *callback_args, **callback_kwargs)
               ^^^^^^^^^^^^^^^^^^^^^^^^^^^^^^^^^^^^^^^^^^^^^^^^^^^^^^^^^^^^
  File "/home/kesley/Documents/house-management/backend/venv/lib/python3.11/site-packages/django/views/decorators/csrf.py", line 65, in _view_wrapper
    return view_func(request, *args, **kwargs)
           ^^^^^^^^^^^^^^^^^^^^^^^^^^^^^^^^^^^
  File "/home/kesley/Documents/house-management/backend/venv/lib/python3.11/site-packages/django/views/generic/base.py", line 104, in view
    return self.dispatch(request, *args, **kwargs)
           ^^^^^^^^^^^^^^^^^^^^^^^^^^^^^^^^^^^^^^^
  File "/home/kesley/Documents/house-management/backend/venv/lib/python3.11/site-packages/rest_framework/views.py", line 511, in dispatch
    self.response = self.finalize_response(request, response, *args, **kwargs)
                    ^^^^^^^^^^^^^^^^^^^^^^^^^^^^^^^^^^^^^^^^^^^^^^^^^^^^^^^^^^
  File "/home/kesley/Documents/house-management/backend/venv/lib/python3.11/site-packages/rest_framework/views.py", line 423, in finalize_response
    assert isinstance(response, HttpResponseBase), (
AssertionError: Expected a `Response`, `HttpResponse` or `HttpStreamingResponse` to be returned from the view, but received a `<class 'NoneType'>`
"POST /categories/category/create/ HTTP/1.1" 500 84674
Internal Server Error: /categories/category/create/
Traceback (most recent call last):
  File "/home/kesley/Documents/house-management/backend/venv/lib/python3.11/site-packages/django/core/handlers/exception.py", line 55, in inner
    response = get_response(request)
               ^^^^^^^^^^^^^^^^^^^^^
  File "/home/kesley/Documents/house-management/backend/venv/lib/python3.11/site-packages/django/core/handlers/base.py", line 197, in _get_response
    response = wrapped_callback(request, *callback_args, **callback_kwargs)
               ^^^^^^^^^^^^^^^^^^^^^^^^^^^^^^^^^^^^^^^^^^^^^^^^^^^^^^^^^^^^
  File "/home/kesley/Documents/house-management/backend/venv/lib/python3.11/site-packages/django/views/decorators/csrf.py", line 65, in _view_wrapper
    return view_func(request, *args, **kwargs)
           ^^^^^^^^^^^^^^^^^^^^^^^^^^^^^^^^^^^
  File "/home/kesley/Documents/house-management/backend/venv/lib/python3.11/site-packages/django/views/generic/base.py", line 104, in view
    return self.dispatch(request, *args, **kwargs)
           ^^^^^^^^^^^^^^^^^^^^^^^^^^^^^^^^^^^^^^^
  File "/home/kesley/Documents/house-management/backend/venv/lib/python3.11/site-packages/rest_framework/views.py", line 511, in dispatch
    self.response = self.finalize_response(request, response, *args, **kwargs)
                    ^^^^^^^^^^^^^^^^^^^^^^^^^^^^^^^^^^^^^^^^^^^^^^^^^^^^^^^^^^
  File "/home/kesley/Documents/house-management/backend/venv/lib/python3.11/site-packages/rest_framework/views.py", line 423, in finalize_response
    assert isinstance(response, HttpResponseBase), (
AssertionError: Expected a `Response`, `HttpResponse` or `HttpStreamingResponse` to be returned from the view, but received a `<class 'NoneType'>`
"POST /categories/category/create/ HTTP/1.1" 500 84674
Internal Server Error: /categories/category/create/
Traceback (most recent call last):
  File "/home/kesley/Documents/house-management/backend/venv/lib/python3.11/site-packages/django/core/handlers/exception.py", line 55, in inner
    response = get_response(request)
               ^^^^^^^^^^^^^^^^^^^^^
  File "/home/kesley/Documents/house-management/backend/venv/lib/python3.11/site-packages/django/core/handlers/base.py", line 197, in _get_response
    response = wrapped_callback(request, *callback_args, **callback_kwargs)
               ^^^^^^^^^^^^^^^^^^^^^^^^^^^^^^^^^^^^^^^^^^^^^^^^^^^^^^^^^^^^
  File "/home/kesley/Documents/house-management/backend/venv/lib/python3.11/site-packages/django/views/decorators/csrf.py", line 65, in _view_wrapper
    return view_func(request, *args, **kwargs)
           ^^^^^^^^^^^^^^^^^^^^^^^^^^^^^^^^^^^
  File "/home/kesley/Documents/house-management/backend/venv/lib/python3.11/site-packages/django/views/generic/base.py", line 104, in view
    return self.dispatch(request, *args, **kwargs)
           ^^^^^^^^^^^^^^^^^^^^^^^^^^^^^^^^^^^^^^^
  File "/home/kesley/Documents/house-management/backend/venv/lib/python3.11/site-packages/rest_framework/views.py", line 511, in dispatch
    self.response = self.finalize_response(request, response, *args, **kwargs)
                    ^^^^^^^^^^^^^^^^^^^^^^^^^^^^^^^^^^^^^^^^^^^^^^^^^^^^^^^^^^
  File "/home/kesley/Documents/house-management/backend/venv/lib/python3.11/site-packages/rest_framework/views.py", line 423, in finalize_response
    assert isinstance(response, HttpResponseBase), (
AssertionError: Expected a `Response`, `HttpResponse` or `HttpStreamingResponse` to be returned from the view, but received a `<class 'NoneType'>`
"POST /categories/category/create/ HTTP/1.1" 500 84674
Internal Server Error: /categories/category/create/
Traceback (most recent call last):
  File "/home/kesley/Documents/house-management/backend/venv/lib/python3.11/site-packages/django/core/handlers/exception.py", line 55, in inner
    response = get_response(request)
               ^^^^^^^^^^^^^^^^^^^^^
  File "/home/kesley/Documents/house-management/backend/venv/lib/python3.11/site-packages/django/core/handlers/base.py", line 197, in _get_response
    response = wrapped_callback(request, *callback_args, **callback_kwargs)
               ^^^^^^^^^^^^^^^^^^^^^^^^^^^^^^^^^^^^^^^^^^^^^^^^^^^^^^^^^^^^
  File "/home/kesley/Documents/house-management/backend/venv/lib/python3.11/site-packages/django/views/decorators/csrf.py", line 65, in _view_wrapper
    return view_func(request, *args, **kwargs)
           ^^^^^^^^^^^^^^^^^^^^^^^^^^^^^^^^^^^
  File "/home/kesley/Documents/house-management/backend/venv/lib/python3.11/site-packages/django/views/generic/base.py", line 104, in view
    return self.dispatch(request, *args, **kwargs)
           ^^^^^^^^^^^^^^^^^^^^^^^^^^^^^^^^^^^^^^^
  File "/home/kesley/Documents/house-management/backend/venv/lib/python3.11/site-packages/rest_framework/views.py", line 511, in dispatch
    self.response = self.finalize_response(request, response, *args, **kwargs)
                    ^^^^^^^^^^^^^^^^^^^^^^^^^^^^^^^^^^^^^^^^^^^^^^^^^^^^^^^^^^
  File "/home/kesley/Documents/house-management/backend/venv/lib/python3.11/site-packages/rest_framework/views.py", line 423, in finalize_response
    assert isinstance(response, HttpResponseBase), (
AssertionError: Expected a `Response`, `HttpResponse` or `HttpStreamingResponse` to be returned from the view, but received a `<class 'NoneType'>`
"POST /categories/category/create/ HTTP/1.1" 500 84674
Internal Server Error: /categories/category/create/
Traceback (most recent call last):
  File "/home/kesley/Documents/house-management/backend/venv/lib/python3.11/site-packages/django/core/handlers/exception.py", line 55, in inner
    response = get_response(request)
               ^^^^^^^^^^^^^^^^^^^^^
  File "/home/kesley/Documents/house-management/backend/venv/lib/python3.11/site-packages/django/core/handlers/base.py", line 197, in _get_response
    response = wrapped_callback(request, *callback_args, **callback_kwargs)
               ^^^^^^^^^^^^^^^^^^^^^^^^^^^^^^^^^^^^^^^^^^^^^^^^^^^^^^^^^^^^
  File "/home/kesley/Documents/house-management/backend/venv/lib/python3.11/site-packages/django/views/decorators/csrf.py", line 65, in _view_wrapper
    return view_func(request, *args, **kwargs)
           ^^^^^^^^^^^^^^^^^^^^^^^^^^^^^^^^^^^
  File "/home/kesley/Documents/house-management/backend/venv/lib/python3.11/site-packages/django/views/generic/base.py", line 104, in view
    return self.dispatch(request, *args, **kwargs)
           ^^^^^^^^^^^^^^^^^^^^^^^^^^^^^^^^^^^^^^^
  File "/home/kesley/Documents/house-management/backend/venv/lib/python3.11/site-packages/rest_framework/views.py", line 511, in dispatch
    self.response = self.finalize_response(request, response, *args, **kwargs)
                    ^^^^^^^^^^^^^^^^^^^^^^^^^^^^^^^^^^^^^^^^^^^^^^^^^^^^^^^^^^
  File "/home/kesley/Documents/house-management/backend/venv/lib/python3.11/site-packages/rest_framework/views.py", line 423, in finalize_response
    assert isinstance(response, HttpResponseBase), (
AssertionError: Expected a `Response`, `HttpResponse` or `HttpStreamingResponse` to be returned from the view, but received a `<class 'NoneType'>`
"POST /categories/category/create/ HTTP/1.1" 500 84674
Internal Server Error: /categories/category/create/
Traceback (most recent call last):
  File "/home/kesley/Documents/house-management/backend/venv/lib/python3.11/site-packages/django/core/handlers/exception.py", line 55, in inner
    response = get_response(request)
               ^^^^^^^^^^^^^^^^^^^^^
  File "/home/kesley/Documents/house-management/backend/venv/lib/python3.11/site-packages/django/core/handlers/base.py", line 197, in _get_response
    response = wrapped_callback(request, *callback_args, **callback_kwargs)
               ^^^^^^^^^^^^^^^^^^^^^^^^^^^^^^^^^^^^^^^^^^^^^^^^^^^^^^^^^^^^
  File "/home/kesley/Documents/house-management/backend/venv/lib/python3.11/site-packages/django/views/decorators/csrf.py", line 65, in _view_wrapper
    return view_func(request, *args, **kwargs)
           ^^^^^^^^^^^^^^^^^^^^^^^^^^^^^^^^^^^
  File "/home/kesley/Documents/house-management/backend/venv/lib/python3.11/site-packages/django/views/generic/base.py", line 104, in view
    return self.dispatch(request, *args, **kwargs)
           ^^^^^^^^^^^^^^^^^^^^^^^^^^^^^^^^^^^^^^^
  File "/home/kesley/Documents/house-management/backend/venv/lib/python3.11/site-packages/rest_framework/views.py", line 511, in dispatch
    self.response = self.finalize_response(request, response, *args, **kwargs)
                    ^^^^^^^^^^^^^^^^^^^^^^^^^^^^^^^^^^^^^^^^^^^^^^^^^^^^^^^^^^
  File "/home/kesley/Documents/house-management/backend/venv/lib/python3.11/site-packages/rest_framework/views.py", line 423, in finalize_response
    assert isinstance(response, HttpResponseBase), (
AssertionError: Expected a `Response`, `HttpResponse` or `HttpStreamingResponse` to be returned from the view, but received a `<class 'NoneType'>`
"POST /categories/category/create/ HTTP/1.1" 500 84674
Internal Server Error: /categories/category/create/
Traceback (most recent call last):
  File "/home/kesley/Documents/house-management/backend/venv/lib/python3.11/site-packages/django/core/handlers/exception.py", line 55, in inner
    response = get_response(request)
               ^^^^^^^^^^^^^^^^^^^^^
  File "/home/kesley/Documents/house-management/backend/venv/lib/python3.11/site-packages/django/core/handlers/base.py", line 197, in _get_response
    response = wrapped_callback(request, *callback_args, **callback_kwargs)
               ^^^^^^^^^^^^^^^^^^^^^^^^^^^^^^^^^^^^^^^^^^^^^^^^^^^^^^^^^^^^
  File "/home/kesley/Documents/house-management/backend/venv/lib/python3.11/site-packages/django/views/decorators/csrf.py", line 65, in _view_wrapper
    return view_func(request, *args, **kwargs)
           ^^^^^^^^^^^^^^^^^^^^^^^^^^^^^^^^^^^
  File "/home/kesley/Documents/house-management/backend/venv/lib/python3.11/site-packages/django/views/generic/base.py", line 104, in view
    return self.dispatch(request, *args, **kwargs)
           ^^^^^^^^^^^^^^^^^^^^^^^^^^^^^^^^^^^^^^^
  File "/home/kesley/Documents/house-management/backend/venv/lib/python3.11/site-packages/rest_framework/views.py", line 511, in dispatch
    self.response = self.finalize_response(request, response, *args, **kwargs)
                    ^^^^^^^^^^^^^^^^^^^^^^^^^^^^^^^^^^^^^^^^^^^^^^^^^^^^^^^^^^
  File "/home/kesley/Documents/house-management/backend/venv/lib/python3.11/site-packages/rest_framework/views.py", line 423, in finalize_response
    assert isinstance(response, HttpResponseBase), (
AssertionError: Expected a `Response`, `HttpResponse` or `HttpStreamingResponse` to be returned from the view, but received a `<class 'NoneType'>`
"POST /categories/category/create/ HTTP/1.1" 500 84674
Internal Server Error: /categories/category/create/
Traceback (most recent call last):
  File "/home/kesley/Documents/house-management/backend/venv/lib/python3.11/site-packages/django/core/handlers/exception.py", line 55, in inner
    response = get_response(request)
               ^^^^^^^^^^^^^^^^^^^^^
  File "/home/kesley/Documents/house-management/backend/venv/lib/python3.11/site-packages/django/core/handlers/base.py", line 197, in _get_response
    response = wrapped_callback(request, *callback_args, **callback_kwargs)
               ^^^^^^^^^^^^^^^^^^^^^^^^^^^^^^^^^^^^^^^^^^^^^^^^^^^^^^^^^^^^
  File "/home/kesley/Documents/house-management/backend/venv/lib/python3.11/site-packages/django/views/decorators/csrf.py", line 65, in _view_wrapper
    return view_func(request, *args, **kwargs)
           ^^^^^^^^^^^^^^^^^^^^^^^^^^^^^^^^^^^
  File "/home/kesley/Documents/house-management/backend/venv/lib/python3.11/site-packages/django/views/generic/base.py", line 104, in view
    return self.dispatch(request, *args, **kwargs)
           ^^^^^^^^^^^^^^^^^^^^^^^^^^^^^^^^^^^^^^^
  File "/home/kesley/Documents/house-management/backend/venv/lib/python3.11/site-packages/rest_framework/views.py", line 511, in dispatch
    self.response = self.finalize_response(request, response, *args, **kwargs)
                    ^^^^^^^^^^^^^^^^^^^^^^^^^^^^^^^^^^^^^^^^^^^^^^^^^^^^^^^^^^
  File "/home/kesley/Documents/house-management/backend/venv/lib/python3.11/site-packages/rest_framework/views.py", line 423, in finalize_response
    assert isinstance(response, HttpResponseBase), (
AssertionError: Expected a `Response`, `HttpResponse` or `HttpStreamingResponse` to be returned from the view, but received a `<class 'NoneType'>`
"POST /categories/category/create/ HTTP/1.1" 500 84674
Internal Server Error: /categories/category/create/
Traceback (most recent call last):
  File "/home/kesley/Documents/house-management/backend/venv/lib/python3.11/site-packages/django/core/handlers/exception.py", line 55, in inner
    response = get_response(request)
               ^^^^^^^^^^^^^^^^^^^^^
  File "/home/kesley/Documents/house-management/backend/venv/lib/python3.11/site-packages/django/core/handlers/base.py", line 197, in _get_response
    response = wrapped_callback(request, *callback_args, **callback_kwargs)
               ^^^^^^^^^^^^^^^^^^^^^^^^^^^^^^^^^^^^^^^^^^^^^^^^^^^^^^^^^^^^
  File "/home/kesley/Documents/house-management/backend/venv/lib/python3.11/site-packages/django/views/decorators/csrf.py", line 65, in _view_wrapper
    return view_func(request, *args, **kwargs)
           ^^^^^^^^^^^^^^^^^^^^^^^^^^^^^^^^^^^
  File "/home/kesley/Documents/house-management/backend/venv/lib/python3.11/site-packages/django/views/generic/base.py", line 104, in view
    return self.dispatch(request, *args, **kwargs)
           ^^^^^^^^^^^^^^^^^^^^^^^^^^^^^^^^^^^^^^^
  File "/home/kesley/Documents/house-management/backend/venv/lib/python3.11/site-packages/rest_framework/views.py", line 511, in dispatch
    self.response = self.finalize_response(request, response, *args, **kwargs)
                    ^^^^^^^^^^^^^^^^^^^^^^^^^^^^^^^^^^^^^^^^^^^^^^^^^^^^^^^^^^
  File "/home/kesley/Documents/house-management/backend/venv/lib/python3.11/site-packages/rest_framework/views.py", line 423, in finalize_response
    assert isinstance(response, HttpResponseBase), (
AssertionError: Expected a `Response`, `HttpResponse` or `HttpStreamingResponse` to be returned from the view, but received a `<class 'NoneType'>`
"POST /categories/category/create/ HTTP/1.1" 500 84674
relation "category_management_category" does not exist
LINE 1: INSERT INTO "category_management_category" ("created_by_id",...
                    ^
Traceback (most recent call last):
  File "/home/kesley/Documents/house-management/backend/venv/lib/python3.11/site-packages/django/db/backends/utils.py", line 105, in _execute
    return self.cursor.execute(sql, params)
           ^^^^^^^^^^^^^^^^^^^^^^^^^^^^^^^^
psycopg2.errors.UndefinedTable: relation "category_management_category" does not exist
LINE 1: INSERT INTO "category_management_category" ("created_by_id",...
                    ^


The above exception was the direct cause of the following exception:

Traceback (most recent call last):
  File "/home/kesley/Documents/house-management/backend/category_management/views/CreateCategory.py", line 25, in post
    services.create_category()
  File "/home/kesley/Documents/house-management/backend/category_management/services.py", line 16, in create_category
    Category.objects.create(name=name, type=type, created_by=user)
  File "/home/kesley/Documents/house-management/backend/venv/lib/python3.11/site-packages/django/db/models/manager.py", line 87, in manager_method
    return getattr(self.get_queryset(), name)(*args, **kwargs)
           ^^^^^^^^^^^^^^^^^^^^^^^^^^^^^^^^^^^^^^^^^^^^^^^^^^^
  File "/home/kesley/Documents/house-management/backend/venv/lib/python3.11/site-packages/django/db/models/query.py", line 677, in create
    obj.save(force_insert=True, using=self.db)
  File "/home/kesley/Documents/house-management/backend/venv/lib/python3.11/site-packages/django/db/models/base.py", line 814, in save
    self.save_base(
  File "/home/kesley/Documents/house-management/backend/venv/lib/python3.11/site-packages/django/db/models/base.py", line 901, in save_base
    updated = self._save_table(
              ^^^^^^^^^^^^^^^^^
  File "/home/kesley/Documents/house-management/backend/venv/lib/python3.11/site-packages/django/db/models/base.py", line 1059, in _save_table
    results = self._do_insert(
              ^^^^^^^^^^^^^^^^
  File "/home/kesley/Documents/house-management/backend/venv/lib/python3.11/site-packages/django/db/models/base.py", line 1100, in _do_insert
    return manager._insert(
           ^^^^^^^^^^^^^^^^
  File "/home/kesley/Documents/house-management/backend/venv/lib/python3.11/site-packages/django/db/models/manager.py", line 87, in manager_method
    return getattr(self.get_queryset(), name)(*args, **kwargs)
           ^^^^^^^^^^^^^^^^^^^^^^^^^^^^^^^^^^^^^^^^^^^^^^^^^^^
  File "/home/kesley/Documents/house-management/backend/venv/lib/python3.11/site-packages/django/db/models/query.py", line 1845, in _insert
    return query.get_compiler(using=using).execute_sql(returning_fields)
           ^^^^^^^^^^^^^^^^^^^^^^^^^^^^^^^^^^^^^^^^^^^^^^^^^^^^^^^^^^^^^
  File "/home/kesley/Documents/house-management/backend/venv/lib/python3.11/site-packages/django/db/models/sql/compiler.py", line 1822, in execute_sql
    cursor.execute(sql, params)
  File "/home/kesley/Documents/house-management/backend/venv/lib/python3.11/site-packages/django/db/backends/utils.py", line 122, in execute
    return super().execute(sql, params)
           ^^^^^^^^^^^^^^^^^^^^^^^^^^^^
  File "/home/kesley/Documents/house-management/backend/venv/lib/python3.11/site-packages/django/db/backends/utils.py", line 79, in execute
    return self._execute_with_wrappers(
           ^^^^^^^^^^^^^^^^^^^^^^^^^^^^
  File "/home/kesley/Documents/house-management/backend/venv/lib/python3.11/site-packages/django/db/backends/utils.py", line 92, in _execute_with_wrappers
    return executor(sql, params, many, context)
           ^^^^^^^^^^^^^^^^^^^^^^^^^^^^^^^^^^^^
  File "/home/kesley/Documents/house-management/backend/venv/lib/python3.11/site-packages/django/db/backends/utils.py", line 100, in _execute
    with self.db.wrap_database_errors:
  File "/home/kesley/Documents/house-management/backend/venv/lib/python3.11/site-packages/django/db/utils.py", line 91, in __exit__
    raise dj_exc_value.with_traceback(traceback) from exc_value
  File "/home/kesley/Documents/house-management/backend/venv/lib/python3.11/site-packages/django/db/backends/utils.py", line 105, in _execute
    return self.cursor.execute(sql, params)
           ^^^^^^^^^^^^^^^^^^^^^^^^^^^^^^^^
django.db.utils.ProgrammingError: relation "category_management_category" does not exist
LINE 1: INSERT INTO "category_management_category" ("created_by_id",...
                    ^

Internal Server Error: /categories/category/create/
"POST /categories/category/create/ HTTP/1.1" 500 38
Internal Server Error: /categories/subcategory/create/
"POST /categories/subcategory/create/ HTTP/1.1" 500 36
'category'
Traceback (most recent call last):
  File "/home/kesley/Documents/house-management/backend/category_management/views/CreateSubcategory.py", line 23, in post
    serializer.is_valid(raise_exception=True)
  File "/home/kesley/Documents/house-management/backend/venv/lib/python3.11/site-packages/rest_framework/serializers.py", line 227, in is_valid
    self._validated_data = self.run_validation(self.initial_data)
                           ^^^^^^^^^^^^^^^^^^^^^^^^^^^^^^^^^^^^^^
  File "/home/kesley/Documents/house-management/backend/venv/lib/python3.11/site-packages/rest_framework/serializers.py", line 426, in run_validation
    value = self.to_internal_value(data)
            ^^^^^^^^^^^^^^^^^^^^^^^^^^^^
  File "/home/kesley/Documents/house-management/backend/category_management/serializers.py", line 25, in to_internal_value
    category = Category.objects.get(name=data['category'])
                                         ~~~~^^^^^^^^^^^^
KeyError: 'category'
Internal Server Error: /categories/subcategory/create/
"POST /categories/subcategory/create/ HTTP/1.1" 500 38
'category'
Traceback (most recent call last):
  File "/home/kesley/Documents/house-management/backend/category_management/views/CreateSubcategory.py", line 23, in post
    serializer.is_valid(raise_exception=True)
  File "/home/kesley/Documents/house-management/backend/venv/lib/python3.11/site-packages/rest_framework/serializers.py", line 227, in is_valid
    self._validated_data = self.run_validation(self.initial_data)
                           ^^^^^^^^^^^^^^^^^^^^^^^^^^^^^^^^^^^^^^
  File "/home/kesley/Documents/house-management/backend/venv/lib/python3.11/site-packages/rest_framework/serializers.py", line 426, in run_validation
    value = self.to_internal_value(data)
            ^^^^^^^^^^^^^^^^^^^^^^^^^^^^
  File "/home/kesley/Documents/house-management/backend/category_management/serializers.py", line 25, in to_internal_value
    category = Category.objects.get(name=data['category'])
                                         ~~~~^^^^^^^^^^^^
KeyError: 'category'
Internal Server Error: /categories/subcategory/create/
"POST /categories/subcategory/create/ HTTP/1.1" 500 38
'category'
Traceback (most recent call last):
  File "/home/kesley/Documents/house-management/backend/category_management/views/CreateSubcategory.py", line 23, in post
    serializer.is_valid(raise_exception=True)
  File "/home/kesley/Documents/house-management/backend/venv/lib/python3.11/site-packages/rest_framework/serializers.py", line 227, in is_valid
    self._validated_data = self.run_validation(self.initial_data)
                           ^^^^^^^^^^^^^^^^^^^^^^^^^^^^^^^^^^^^^^
  File "/home/kesley/Documents/house-management/backend/venv/lib/python3.11/site-packages/rest_framework/serializers.py", line 426, in run_validation
    value = self.to_internal_value(data)
            ^^^^^^^^^^^^^^^^^^^^^^^^^^^^
  File "/home/kesley/Documents/house-management/backend/category_management/serializers.py", line 25, in to_internal_value
    category = Category.objects.get(name=data['category'])
                                         ~~~~^^^^^^^^^^^^
KeyError: 'category'
Internal Server Error: /categories/subcategory/create/
"POST /categories/subcategory/create/ HTTP/1.1" 500 38
Internal Server Error: /categories/sub/9/create/
Traceback (most recent call last):
  File "/home/kesley/Documents/house-management/backend/venv/lib/python3.11/site-packages/django/core/handlers/exception.py", line 55, in inner
    response = get_response(request)
               ^^^^^^^^^^^^^^^^^^^^^
  File "/home/kesley/Documents/house-management/backend/venv/lib/python3.11/site-packages/django/core/handlers/base.py", line 197, in _get_response
    response = wrapped_callback(request, *callback_args, **callback_kwargs)
               ^^^^^^^^^^^^^^^^^^^^^^^^^^^^^^^^^^^^^^^^^^^^^^^^^^^^^^^^^^^^
  File "/home/kesley/Documents/house-management/backend/venv/lib/python3.11/site-packages/django/views/decorators/csrf.py", line 65, in _view_wrapper
    return view_func(request, *args, **kwargs)
           ^^^^^^^^^^^^^^^^^^^^^^^^^^^^^^^^^^^
  File "/home/kesley/Documents/house-management/backend/venv/lib/python3.11/site-packages/django/views/generic/base.py", line 104, in view
    return self.dispatch(request, *args, **kwargs)
           ^^^^^^^^^^^^^^^^^^^^^^^^^^^^^^^^^^^^^^^
  File "/home/kesley/Documents/house-management/backend/venv/lib/python3.11/site-packages/rest_framework/views.py", line 509, in dispatch
    response = self.handle_exception(exc)
               ^^^^^^^^^^^^^^^^^^^^^^^^^^
  File "/home/kesley/Documents/house-management/backend/venv/lib/python3.11/site-packages/rest_framework/views.py", line 469, in handle_exception
    self.raise_uncaught_exception(exc)
  File "/home/kesley/Documents/house-management/backend/venv/lib/python3.11/site-packages/rest_framework/views.py", line 480, in raise_uncaught_exception
    raise exc
  File "/home/kesley/Documents/house-management/backend/venv/lib/python3.11/site-packages/rest_framework/views.py", line 506, in dispatch
    response = handler(request, *args, **kwargs)
               ^^^^^^^^^^^^^^^^^^^^^^^^^^^^^^^^^
TypeError: CreateSubcategoryView.post() got an unexpected keyword argument 'category_id'
"POST /categories/sub/9/create/ HTTP/1.1" 500 93853
'description'
Traceback (most recent call last):
  File "/home/kesley/Documents/house-management/backend/category_management/views/CreateSubcategory.py", line 25, in post
    services.create_subcategory()
  File "/home/kesley/Documents/house-management/backend/category_management/services.py", line 29, in create_subcategory
    description = self.data['description']
                  ~~~~~~~~~^^^^^^^^^^^^^^^
KeyError: 'description'
Internal Server Error: /categories/sub/9/create/
"POST /categories/sub/9/create/ HTTP/1.1" 500 38
'description'
Traceback (most recent call last):
  File "/home/kesley/Documents/house-management/backend/category_management/views/CreateSubcategory.py", line 25, in post
    services.create_subcategory()
  File "/home/kesley/Documents/house-management/backend/category_management/services.py", line 29, in create_subcategory
    description = self.data['description']
                  ~~~~~~~~~^^^^^^^^^^^^^^^
KeyError: 'description'
Internal Server Error: /categories/sub/9/create/
"POST /categories/sub/9/create/ HTTP/1.1" 500 38
Field 'id' expected a number but got 'kefsner'.
Traceback (most recent call last):
  File "/home/kesley/Documents/house-management/backend/venv/lib/python3.11/site-packages/django/db/models/fields/__init__.py", line 2112, in get_prep_value
    return int(value)
           ^^^^^^^^^^
ValueError: invalid literal for int() with base 10: 'kefsner'

The above exception was the direct cause of the following exception:

Traceback (most recent call last):
  File "/home/kesley/Documents/house-management/backend/account_management/views/CreateAccount.py", line 48, in post
    services.create_account()
  File "/home/kesley/Documents/house-management/backend/account_management/services.py", line 15, in create_account
    user = User.objects.get(id=user)
           ^^^^^^^^^^^^^^^^^^^^^^^^^
  File "/home/kesley/Documents/house-management/backend/venv/lib/python3.11/site-packages/django/db/models/manager.py", line 87, in manager_method
    return getattr(self.get_queryset(), name)(*args, **kwargs)
           ^^^^^^^^^^^^^^^^^^^^^^^^^^^^^^^^^^^^^^^^^^^^^^^^^^^
  File "/home/kesley/Documents/house-management/backend/venv/lib/python3.11/site-packages/django/db/models/query.py", line 633, in get
    clone = self._chain() if self.query.combinator else self.filter(*args, **kwargs)
                                                        ^^^^^^^^^^^^^^^^^^^^^^^^^^^^
  File "/home/kesley/Documents/house-management/backend/venv/lib/python3.11/site-packages/django/db/models/query.py", line 1476, in filter
    return self._filter_or_exclude(False, args, kwargs)
           ^^^^^^^^^^^^^^^^^^^^^^^^^^^^^^^^^^^^^^^^^^^^
  File "/home/kesley/Documents/house-management/backend/venv/lib/python3.11/site-packages/django/db/models/query.py", line 1494, in _filter_or_exclude
    clone._filter_or_exclude_inplace(negate, args, kwargs)
  File "/home/kesley/Documents/house-management/backend/venv/lib/python3.11/site-packages/django/db/models/query.py", line 1501, in _filter_or_exclude_inplace
    self._query.add_q(Q(*args, **kwargs))
  File "/home/kesley/Documents/house-management/backend/venv/lib/python3.11/site-packages/django/db/models/sql/query.py", line 1600, in add_q
    clause, _ = self._add_q(q_object, self.used_aliases)
                ^^^^^^^^^^^^^^^^^^^^^^^^^^^^^^^^^^^^^^^^
  File "/home/kesley/Documents/house-management/backend/venv/lib/python3.11/site-packages/django/db/models/sql/query.py", line 1632, in _add_q
    child_clause, needed_inner = self.build_filter(
                                 ^^^^^^^^^^^^^^^^^^
  File "/home/kesley/Documents/house-management/backend/venv/lib/python3.11/site-packages/django/db/models/sql/query.py", line 1546, in build_filter
    condition = self.build_lookup(lookups, col, value)
                ^^^^^^^^^^^^^^^^^^^^^^^^^^^^^^^^^^^^^^
  File "/home/kesley/Documents/house-management/backend/venv/lib/python3.11/site-packages/django/db/models/sql/query.py", line 1376, in build_lookup
    lookup = lookup_class(lhs, rhs)
             ^^^^^^^^^^^^^^^^^^^^^^
  File "/home/kesley/Documents/house-management/backend/venv/lib/python3.11/site-packages/django/db/models/lookups.py", line 30, in __init__
    self.rhs = self.get_prep_lookup()
               ^^^^^^^^^^^^^^^^^^^^^^
  File "/home/kesley/Documents/house-management/backend/venv/lib/python3.11/site-packages/django/db/models/lookups.py", line 362, in get_prep_lookup
    return super().get_prep_lookup()
           ^^^^^^^^^^^^^^^^^^^^^^^^^
  File "/home/kesley/Documents/house-management/backend/venv/lib/python3.11/site-packages/django/db/models/lookups.py", line 88, in get_prep_lookup
    return self.lhs.output_field.get_prep_value(self.rhs)
           ^^^^^^^^^^^^^^^^^^^^^^^^^^^^^^^^^^^^^^^^^^^^^^
  File "/home/kesley/Documents/house-management/backend/venv/lib/python3.11/site-packages/django/db/models/fields/__init__.py", line 2114, in get_prep_value
    raise e.__class__(
ValueError: Field 'id' expected a number but got 'kefsner'.
Internal Server Error: /accounts/create/
"POST /accounts/create/ HTTP/1.1" 500 38
'due_date'
Traceback (most recent call last):
  File "/home/kesley/Documents/house-management/backend/creditcard_management/views/CreateCreditCard.py", line 26, in post
    services.create_credit_card()
  File "/home/kesley/Documents/house-management/backend/creditcard_management/services.py", line 18, in create_credit_card
    due_date = self.data['due_date']
               ~~~~~~~~~^^^^^^^^^^^^
KeyError: 'due_date'
Internal Server Error: /credit_cards/create/
"POST /credit_cards/create/ HTTP/1.1" 500 38
'due_date'
Traceback (most recent call last):
  File "/home/kesley/Documents/house-management/backend/creditcard_management/views/CreateCreditCard.py", line 26, in post
    services.create_credit_card()
  File "/home/kesley/Documents/house-management/backend/creditcard_management/services.py", line 18, in create_credit_card
    due_date = self.data['due_date']
               ~~~~~~~~~^^^^^^^^^^^^
KeyError: 'due_date'
Internal Server Error: /credit_cards/create/
"POST /credit_cards/create/ HTTP/1.1" 500 38
column "due_day" of relation "creditcard_management_creditcard" does not exist
LINE 1: ...eated_by_id", "created_at", "name", "account_id", "due_day",...
                                                             ^
Traceback (most recent call last):
  File "/home/kesley/Documents/house-management/backend/venv/lib/python3.11/site-packages/django/db/backends/utils.py", line 105, in _execute
    return self.cursor.execute(sql, params)
           ^^^^^^^^^^^^^^^^^^^^^^^^^^^^^^^^
psycopg2.errors.UndefinedColumn: column "due_day" of relation "creditcard_management_creditcard" does not exist
LINE 1: ...eated_by_id", "created_at", "name", "account_id", "due_day",...
                                                             ^


The above exception was the direct cause of the following exception:

Traceback (most recent call last):
  File "/home/kesley/Documents/house-management/backend/creditcard_management/views/CreateCreditCard.py", line 26, in post
    services.create_credit_card()
  File "/home/kesley/Documents/house-management/backend/creditcard_management/services.py", line 22, in create_credit_card
    CreditCard.objects.create(name=name, account=account, due_day=due_day, limit=limit, remaining_limit=limit, created_by=created_by)
  File "/home/kesley/Documents/house-management/backend/venv/lib/python3.11/site-packages/django/db/models/manager.py", line 87, in manager_method
    return getattr(self.get_queryset(), name)(*args, **kwargs)
           ^^^^^^^^^^^^^^^^^^^^^^^^^^^^^^^^^^^^^^^^^^^^^^^^^^^
  File "/home/kesley/Documents/house-management/backend/venv/lib/python3.11/site-packages/django/db/models/query.py", line 677, in create
    obj.save(force_insert=True, using=self.db)
  File "/home/kesley/Documents/house-management/backend/venv/lib/python3.11/site-packages/django/db/models/base.py", line 814, in save
    self.save_base(
  File "/home/kesley/Documents/house-management/backend/venv/lib/python3.11/site-packages/django/db/models/base.py", line 901, in save_base
    updated = self._save_table(
              ^^^^^^^^^^^^^^^^^
  File "/home/kesley/Documents/house-management/backend/venv/lib/python3.11/site-packages/django/db/models/base.py", line 1059, in _save_table
    results = self._do_insert(
              ^^^^^^^^^^^^^^^^
  File "/home/kesley/Documents/house-management/backend/venv/lib/python3.11/site-packages/django/db/models/base.py", line 1100, in _do_insert
    return manager._insert(
           ^^^^^^^^^^^^^^^^
  File "/home/kesley/Documents/house-management/backend/venv/lib/python3.11/site-packages/django/db/models/manager.py", line 87, in manager_method
    return getattr(self.get_queryset(), name)(*args, **kwargs)
           ^^^^^^^^^^^^^^^^^^^^^^^^^^^^^^^^^^^^^^^^^^^^^^^^^^^
  File "/home/kesley/Documents/house-management/backend/venv/lib/python3.11/site-packages/django/db/models/query.py", line 1845, in _insert
    return query.get_compiler(using=using).execute_sql(returning_fields)
           ^^^^^^^^^^^^^^^^^^^^^^^^^^^^^^^^^^^^^^^^^^^^^^^^^^^^^^^^^^^^^
  File "/home/kesley/Documents/house-management/backend/venv/lib/python3.11/site-packages/django/db/models/sql/compiler.py", line 1822, in execute_sql
    cursor.execute(sql, params)
  File "/home/kesley/Documents/house-management/backend/venv/lib/python3.11/site-packages/django/db/backends/utils.py", line 122, in execute
    return super().execute(sql, params)
           ^^^^^^^^^^^^^^^^^^^^^^^^^^^^
  File "/home/kesley/Documents/house-management/backend/venv/lib/python3.11/site-packages/django/db/backends/utils.py", line 79, in execute
    return self._execute_with_wrappers(
           ^^^^^^^^^^^^^^^^^^^^^^^^^^^^
  File "/home/kesley/Documents/house-management/backend/venv/lib/python3.11/site-packages/django/db/backends/utils.py", line 92, in _execute_with_wrappers
    return executor(sql, params, many, context)
           ^^^^^^^^^^^^^^^^^^^^^^^^^^^^^^^^^^^^
  File "/home/kesley/Documents/house-management/backend/venv/lib/python3.11/site-packages/django/db/backends/utils.py", line 100, in _execute
    with self.db.wrap_database_errors:
  File "/home/kesley/Documents/house-management/backend/venv/lib/python3.11/site-packages/django/db/utils.py", line 91, in __exit__
    raise dj_exc_value.with_traceback(traceback) from exc_value
  File "/home/kesley/Documents/house-management/backend/venv/lib/python3.11/site-packages/django/db/backends/utils.py", line 105, in _execute
    return self.cursor.execute(sql, params)
           ^^^^^^^^^^^^^^^^^^^^^^^^^^^^^^^^
django.db.utils.ProgrammingError: column "due_day" of relation "creditcard_management_creditcard" does not exist
LINE 1: ...eated_by_id", "created_at", "name", "account_id", "due_day",...
                                                             ^

Internal Server Error: /credit_cards/create/
"POST /credit_cards/create/ HTTP/1.1" 500 38
