Traceback:
2024-01-31 14:00:28.608713
Traceback (most recent call last):
  File "/home/kesley/Documents/house-management/backend/finances/views/CreateTransaction.py", line 25, in post
    if not serializer.is_valid():
           ^^^^^^^^^^^^^^^^^^^^^
  File "/home/kesley/Documents/house-management/backend/venv/lib/python3.11/site-packages/rest_framework/serializers.py", line 227, in is_valid
    self._validated_data = self.run_validation(self.initial_data)
                           ^^^^^^^^^^^^^^^^^^^^^^^^^^^^^^^^^^^^^^
  File "/home/kesley/Documents/house-management/backend/venv/lib/python3.11/site-packages/rest_framework/serializers.py", line 426, in run_validation
    value = self.to_internal_value(data)
            ^^^^^^^^^^^^^^^^^^^^^^^^^^^^
  File "/home/kesley/Documents/house-management/backend/finances/serializers.py", line 11, in to_internal_value
    subcategory = Subcategory.objects.get(name=data['subcategory'])
                  ^^^^^^^^^^^^^^^^^^^^^^^^^^^^^^^^^^^^^^^^^^^^^^^^^
  File "/home/kesley/Documents/house-management/backend/venv/lib/python3.11/site-packages/django/db/models/manager.py", line 87, in manager_method
    return getattr(self.get_queryset(), name)(*args, **kwargs)
           ^^^^^^^^^^^^^^^^^^^^^^^^^^^^^^^^^^^^^^^^^^^^^^^^^^^
  File "/home/kesley/Documents/house-management/backend/venv/lib/python3.11/site-packages/django/db/models/query.py", line 647, in get
    raise self.model.DoesNotExist(
finances.models.Subcategory.DoesNotExist: Subcategory matching query does not exist.
==================================================
Traceback:
2024-01-31 14:03:10.647072
Traceback (most recent call last):
  File "/home/kesley/Documents/house-management/backend/finances/views/CreateTransaction.py", line 25, in post
    if not serializer.is_valid():
           ^^^^^^^^^^^^^^^^^^^^^
  File "/home/kesley/Documents/house-management/backend/venv/lib/python3.11/site-packages/rest_framework/serializers.py", line 227, in is_valid
    self._validated_data = self.run_validation(self.initial_data)
                           ^^^^^^^^^^^^^^^^^^^^^^^^^^^^^^^^^^^^^^
  File "/home/kesley/Documents/house-management/backend/venv/lib/python3.11/site-packages/rest_framework/serializers.py", line 426, in run_validation
    value = self.to_internal_value(data)
            ^^^^^^^^^^^^^^^^^^^^^^^^^^^^
  File "/home/kesley/Documents/house-management/backend/finances/serializers.py", line 14, in to_internal_value
    subcategory = Subcategory.objects.get(name=data['subcategory'])
                  ^^^^^^^^^^^^^^^^^^^^^^^^^^^^^^^^^^^^^^^^^^^^^^^^^
  File "/home/kesley/Documents/house-management/backend/venv/lib/python3.11/site-packages/django/db/models/manager.py", line 87, in manager_method
    return getattr(self.get_queryset(), name)(*args, **kwargs)
           ^^^^^^^^^^^^^^^^^^^^^^^^^^^^^^^^^^^^^^^^^^^^^^^^^^^
  File "/home/kesley/Documents/house-management/backend/venv/lib/python3.11/site-packages/django/db/models/query.py", line 647, in get
    raise self.model.DoesNotExist(
finances.models.Subcategory.DoesNotExist: Subcategory matching query does not exist.
==================================================
Traceback:
2024-01-31 14:03:57.134653
Traceback (most recent call last):
  File "/home/kesley/Documents/house-management/backend/finances/views/CreateTransaction.py", line 25, in post
    if not serializer.is_valid():
           ^^^^^^^^^^^^^^^^^^^^^
  File "/home/kesley/Documents/house-management/backend/venv/lib/python3.11/site-packages/rest_framework/serializers.py", line 227, in is_valid
    self._validated_data = self.run_validation(self.initial_data)
                           ^^^^^^^^^^^^^^^^^^^^^^^^^^^^^^^^^^^^^^
  File "/home/kesley/Documents/house-management/backend/venv/lib/python3.11/site-packages/rest_framework/serializers.py", line 426, in run_validation
    value = self.to_internal_value(data)
            ^^^^^^^^^^^^^^^^^^^^^^^^^^^^
  File "/home/kesley/Documents/house-management/backend/finances/serializers.py", line 15, in to_internal_value
    subcategory = Subcategory.objects.get(name=data['subcategory'])
                  ^^^^^^^^^^^^^^^^^^^^^^^^^^^^^^^^^^^^^^^^^^^^^^^^^
  File "/home/kesley/Documents/house-management/backend/venv/lib/python3.11/site-packages/django/db/models/manager.py", line 87, in manager_method
    return getattr(self.get_queryset(), name)(*args, **kwargs)
           ^^^^^^^^^^^^^^^^^^^^^^^^^^^^^^^^^^^^^^^^^^^^^^^^^^^
  File "/home/kesley/Documents/house-management/backend/venv/lib/python3.11/site-packages/django/db/models/query.py", line 647, in get
    raise self.model.DoesNotExist(
finances.models.Subcategory.DoesNotExist: Subcategory matching query does not exist.
==================================================
Traceback:
2024-01-31 14:04:23.097319
Traceback (most recent call last):
  File "/home/kesley/Documents/house-management/backend/finances/views/CreateTransaction.py", line 26, in post
    if not serializer.is_valid():
           ^^^^^^^^^^^^^^^^^^^^^
  File "/home/kesley/Documents/house-management/backend/venv/lib/python3.11/site-packages/rest_framework/serializers.py", line 227, in is_valid
    self._validated_data = self.run_validation(self.initial_data)
                           ^^^^^^^^^^^^^^^^^^^^^^^^^^^^^^^^^^^^^^
  File "/home/kesley/Documents/house-management/backend/venv/lib/python3.11/site-packages/rest_framework/serializers.py", line 426, in run_validation
    value = self.to_internal_value(data)
            ^^^^^^^^^^^^^^^^^^^^^^^^^^^^
  File "/home/kesley/Documents/house-management/backend/finances/serializers.py", line 14, in to_internal_value
    subcategory = Subcategory.objects.get(name=data['subcategory'])
                  ^^^^^^^^^^^^^^^^^^^^^^^^^^^^^^^^^^^^^^^^^^^^^^^^^
  File "/home/kesley/Documents/house-management/backend/venv/lib/python3.11/site-packages/django/db/models/manager.py", line 87, in manager_method
    return getattr(self.get_queryset(), name)(*args, **kwargs)
           ^^^^^^^^^^^^^^^^^^^^^^^^^^^^^^^^^^^^^^^^^^^^^^^^^^^
  File "/home/kesley/Documents/house-management/backend/venv/lib/python3.11/site-packages/django/db/models/query.py", line 647, in get
    raise self.model.DoesNotExist(
finances.models.Subcategory.DoesNotExist: Subcategory matching query does not exist.
==================================================
Traceback:
2024-01-31 14:04:38.484457
Traceback (most recent call last):
  File "/home/kesley/Documents/house-management/backend/finances/views/CreateTransaction.py", line 26, in post
    if not serializer.is_valid():
           ^^^^^^^^^^^^^^^^^^^^^
  File "/home/kesley/Documents/house-management/backend/venv/lib/python3.11/site-packages/rest_framework/serializers.py", line 227, in is_valid
    self._validated_data = self.run_validation(self.initial_data)
                           ^^^^^^^^^^^^^^^^^^^^^^^^^^^^^^^^^^^^^^
  File "/home/kesley/Documents/house-management/backend/venv/lib/python3.11/site-packages/rest_framework/serializers.py", line 426, in run_validation
    value = self.to_internal_value(data)
            ^^^^^^^^^^^^^^^^^^^^^^^^^^^^
  File "/home/kesley/Documents/house-management/backend/finances/serializers.py", line 14, in to_internal_value
    subcategory = Subcategory.objects.get(name=data['subcategory'])
                  ^^^^^^^^^^^^^^^^^^^^^^^^^^^^^^^^^^^^^^^^^^^^^^^^^
  File "/home/kesley/Documents/house-management/backend/venv/lib/python3.11/site-packages/django/db/models/manager.py", line 87, in manager_method
    return getattr(self.get_queryset(), name)(*args, **kwargs)
           ^^^^^^^^^^^^^^^^^^^^^^^^^^^^^^^^^^^^^^^^^^^^^^^^^^^
  File "/home/kesley/Documents/house-management/backend/venv/lib/python3.11/site-packages/django/db/models/query.py", line 647, in get
    raise self.model.DoesNotExist(
finances.models.Subcategory.DoesNotExist: Subcategory matching query does not exist.
==================================================
Traceback:
2024-01-31 14:06:27.837061
Traceback (most recent call last):
  File "/home/kesley/Documents/house-management/backend/finances/views/CreateTransaction.py", line 26, in post
    if not serializer.is_valid():
           ^^^^^^^^^^^^^^^^^^^^^
  File "/home/kesley/Documents/house-management/backend/venv/lib/python3.11/site-packages/rest_framework/serializers.py", line 227, in is_valid
    self._validated_data = self.run_validation(self.initial_data)
                           ^^^^^^^^^^^^^^^^^^^^^^^^^^^^^^^^^^^^^^
  File "/home/kesley/Documents/house-management/backend/venv/lib/python3.11/site-packages/rest_framework/serializers.py", line 426, in run_validation
    value = self.to_internal_value(data)
            ^^^^^^^^^^^^^^^^^^^^^^^^^^^^
  File "/home/kesley/Documents/house-management/backend/finances/serializers.py", line 14, in to_internal_value
    subcategory = Subcategory.objects.get(name=data['subcategory'])
                  ^^^^^^^^^^^^^^^^^^^^^^^^^^^^^^^^^^^^^^^^^^^^^^^^^
  File "/home/kesley/Documents/house-management/backend/venv/lib/python3.11/site-packages/django/db/models/manager.py", line 87, in manager_method
    return getattr(self.get_queryset(), name)(*args, **kwargs)
           ^^^^^^^^^^^^^^^^^^^^^^^^^^^^^^^^^^^^^^^^^^^^^^^^^^^
  File "/home/kesley/Documents/house-management/backend/venv/lib/python3.11/site-packages/django/db/models/query.py", line 647, in get
    raise self.model.DoesNotExist(
finances.models.Subcategory.DoesNotExist: Subcategory matching query does not exist.
==================================================
Traceback:
2024-01-31 14:07:17.750825
Traceback (most recent call last):
  File "/home/kesley/Documents/house-management/backend/finances/views/CreateTransaction.py", line 26, in post
    if not serializer.is_valid():
           ^^^^^^^^^^^^^^^^^^^^^
  File "/home/kesley/Documents/house-management/backend/venv/lib/python3.11/site-packages/rest_framework/serializers.py", line 227, in is_valid
    self._validated_data = self.run_validation(self.initial_data)
                           ^^^^^^^^^^^^^^^^^^^^^^^^^^^^^^^^^^^^^^
  File "/home/kesley/Documents/house-management/backend/venv/lib/python3.11/site-packages/rest_framework/serializers.py", line 426, in run_validation
    value = self.to_internal_value(data)
            ^^^^^^^^^^^^^^^^^^^^^^^^^^^^
  File "/home/kesley/Documents/house-management/backend/finances/serializers.py", line 14, in to_internal_value
    subcategory = Subcategory.objects.get(name=data['subcategory'])
                  ^^^^^^^^^^^^^^^^^^^^^^^^^^^^^^^^^^^^^^^^^^^^^^^^^
  File "/home/kesley/Documents/house-management/backend/venv/lib/python3.11/site-packages/django/db/models/manager.py", line 87, in manager_method
    return getattr(self.get_queryset(), name)(*args, **kwargs)
           ^^^^^^^^^^^^^^^^^^^^^^^^^^^^^^^^^^^^^^^^^^^^^^^^^^^
  File "/home/kesley/Documents/house-management/backend/venv/lib/python3.11/site-packages/django/db/models/query.py", line 647, in get
    raise self.model.DoesNotExist(
finances.models.Subcategory.DoesNotExist: Subcategory matching query does not exist.
==================================================
Traceback:
2024-01-31 14:10:49.474053
Traceback (most recent call last):
  File "/home/kesley/Documents/house-management/backend/finances/views/CreateTransaction.py", line 26, in post
    if not serializer.is_valid():
           ^^^^^^^^^^^^^^^^^^^^^
  File "/home/kesley/Documents/house-management/backend/venv/lib/python3.11/site-packages/rest_framework/serializers.py", line 227, in is_valid
    self._validated_data = self.run_validation(self.initial_data)
                           ^^^^^^^^^^^^^^^^^^^^^^^^^^^^^^^^^^^^^^
  File "/home/kesley/Documents/house-management/backend/venv/lib/python3.11/site-packages/rest_framework/serializers.py", line 426, in run_validation
    value = self.to_internal_value(data)
            ^^^^^^^^^^^^^^^^^^^^^^^^^^^^
  File "/home/kesley/Documents/house-management/backend/finances/serializers.py", line 14, in to_internal_value
    subcategory = Subcategory.objects.get(name=data['subcategory'])
                  ^^^^^^^^^^^^^^^^^^^^^^^^^^^^^^^^^^^^^^^^^^^^^^^^^
  File "/home/kesley/Documents/house-management/backend/venv/lib/python3.11/site-packages/django/db/models/manager.py", line 87, in manager_method
    return getattr(self.get_queryset(), name)(*args, **kwargs)
           ^^^^^^^^^^^^^^^^^^^^^^^^^^^^^^^^^^^^^^^^^^^^^^^^^^^
  File "/home/kesley/Documents/house-management/backend/venv/lib/python3.11/site-packages/django/db/models/query.py", line 647, in get
    raise self.model.DoesNotExist(
finances.models.Subcategory.DoesNotExist: Subcategory matching query does not exist.
==================================================
Traceback:
2024-01-31 14:10:56.063313
Traceback (most recent call last):
  File "/home/kesley/Documents/house-management/backend/finances/views/CreateTransaction.py", line 26, in post
    if not serializer.is_valid():
           ^^^^^^^^^^^^^^^^^^^^^
  File "/home/kesley/Documents/house-management/backend/venv/lib/python3.11/site-packages/rest_framework/serializers.py", line 227, in is_valid
    self._validated_data = self.run_validation(self.initial_data)
                           ^^^^^^^^^^^^^^^^^^^^^^^^^^^^^^^^^^^^^^
  File "/home/kesley/Documents/house-management/backend/venv/lib/python3.11/site-packages/rest_framework/serializers.py", line 426, in run_validation
    value = self.to_internal_value(data)
            ^^^^^^^^^^^^^^^^^^^^^^^^^^^^
  File "/home/kesley/Documents/house-management/backend/finances/serializers.py", line 14, in to_internal_value
    subcategory = Subcategory.objects.get(name=data['subcategory'])
                  ^^^^^^^^^^^^^^^^^^^^^^^^^^^^^^^^^^^^^^^^^^^^^^^^^
  File "/home/kesley/Documents/house-management/backend/venv/lib/python3.11/site-packages/django/db/models/manager.py", line 87, in manager_method
    return getattr(self.get_queryset(), name)(*args, **kwargs)
           ^^^^^^^^^^^^^^^^^^^^^^^^^^^^^^^^^^^^^^^^^^^^^^^^^^^
  File "/home/kesley/Documents/house-management/backend/venv/lib/python3.11/site-packages/django/db/models/query.py", line 647, in get
    raise self.model.DoesNotExist(
finances.models.Subcategory.DoesNotExist: Subcategory matching query does not exist.
==================================================
Traceback:
2024-01-31 14:11:40.178577
Traceback (most recent call last):
  File "/home/kesley/Documents/house-management/backend/finances/views/CreateTransaction.py", line 26, in post
    if not serializer.is_valid():
           ^^^^^^^^^^^^^^^^^^^^^
  File "/home/kesley/Documents/house-management/backend/venv/lib/python3.11/site-packages/rest_framework/serializers.py", line 227, in is_valid
    self._validated_data = self.run_validation(self.initial_data)
                           ^^^^^^^^^^^^^^^^^^^^^^^^^^^^^^^^^^^^^^
  File "/home/kesley/Documents/house-management/backend/venv/lib/python3.11/site-packages/rest_framework/serializers.py", line 426, in run_validation
    value = self.to_internal_value(data)
            ^^^^^^^^^^^^^^^^^^^^^^^^^^^^
  File "/home/kesley/Documents/house-management/backend/finances/serializers.py", line 14, in to_internal_value
    subcategory = Subcategory.objects.get(name=data['subcategory'])
                  ^^^^^^^^^^^^^^^^^^^^^^^^^^^^^^^^^^^^^^^^^^^^^^^^^
  File "/home/kesley/Documents/house-management/backend/venv/lib/python3.11/site-packages/django/db/models/manager.py", line 87, in manager_method
    return getattr(self.get_queryset(), name)(*args, **kwargs)
           ^^^^^^^^^^^^^^^^^^^^^^^^^^^^^^^^^^^^^^^^^^^^^^^^^^^
  File "/home/kesley/Documents/house-management/backend/venv/lib/python3.11/site-packages/django/db/models/query.py", line 647, in get
    raise self.model.DoesNotExist(
finances.models.Subcategory.DoesNotExist: Subcategory matching query does not exist.
==================================================
Traceback:
2024-01-31 14:12:15.047140
Traceback (most recent call last):
  File "/home/kesley/Documents/house-management/backend/finances/views/CreateTransaction.py", line 26, in post
    if not serializer.is_valid():
           ^^^^^^^^^^^^^^^^^^^^^
  File "/home/kesley/Documents/house-management/backend/venv/lib/python3.11/site-packages/rest_framework/serializers.py", line 227, in is_valid
    self._validated_data = self.run_validation(self.initial_data)
                           ^^^^^^^^^^^^^^^^^^^^^^^^^^^^^^^^^^^^^^
  File "/home/kesley/Documents/house-management/backend/venv/lib/python3.11/site-packages/rest_framework/serializers.py", line 426, in run_validation
    value = self.to_internal_value(data)
            ^^^^^^^^^^^^^^^^^^^^^^^^^^^^
  File "/home/kesley/Documents/house-management/backend/finances/serializers.py", line 14, in to_internal_value
    subcategory = Subcategory.objects.get(name=data['subcategory'])
                  ^^^^^^^^^^^^^^^^^^^^^^^^^^^^^^^^^^^^^^^^^^^^^^^^^
  File "/home/kesley/Documents/house-management/backend/venv/lib/python3.11/site-packages/django/db/models/manager.py", line 87, in manager_method
    return getattr(self.get_queryset(), name)(*args, **kwargs)
           ^^^^^^^^^^^^^^^^^^^^^^^^^^^^^^^^^^^^^^^^^^^^^^^^^^^
  File "/home/kesley/Documents/house-management/backend/venv/lib/python3.11/site-packages/django/db/models/query.py", line 647, in get
    raise self.model.DoesNotExist(
finances.models.Subcategory.DoesNotExist: Subcategory matching query does not exist.
==================================================
Traceback:
2024-01-31 14:12:35.982490
Traceback (most recent call last):
  File "/home/kesley/Documents/house-management/backend/finances/views/CreateTransaction.py", line 26, in post
    if not serializer.is_valid():
           ^^^^^^^^^^^^^^^^^^^^^
  File "/home/kesley/Documents/house-management/backend/venv/lib/python3.11/site-packages/rest_framework/serializers.py", line 227, in is_valid
    self._validated_data = self.run_validation(self.initial_data)
                           ^^^^^^^^^^^^^^^^^^^^^^^^^^^^^^^^^^^^^^
  File "/home/kesley/Documents/house-management/backend/venv/lib/python3.11/site-packages/rest_framework/serializers.py", line 426, in run_validation
    value = self.to_internal_value(data)
            ^^^^^^^^^^^^^^^^^^^^^^^^^^^^
  File "/home/kesley/Documents/house-management/backend/finances/serializers.py", line 14, in to_internal_value
    subcategory = Subcategory.objects.get(name=data['subcategory'])
                  ^^^^^^^^^^^^^^^^^^^^^^^^^^^^^^^^^^^^^^^^^^^^^^^^^
  File "/home/kesley/Documents/house-management/backend/venv/lib/python3.11/site-packages/django/db/models/manager.py", line 87, in manager_method
    return getattr(self.get_queryset(), name)(*args, **kwargs)
           ^^^^^^^^^^^^^^^^^^^^^^^^^^^^^^^^^^^^^^^^^^^^^^^^^^^
  File "/home/kesley/Documents/house-management/backend/venv/lib/python3.11/site-packages/django/db/models/query.py", line 647, in get
    raise self.model.DoesNotExist(
finances.models.Subcategory.DoesNotExist: Subcategory matching query does not exist.
==================================================
Traceback:
2024-01-31 14:16:29.049665
Traceback (most recent call last):
  File "/home/kesley/Documents/house-management/backend/finances/views/CreateTransaction.py", line 26, in post
    if not serializer.is_valid():
           ^^^^^^^^^^^^^^^^^^^^^
  File "/home/kesley/Documents/house-management/backend/venv/lib/python3.11/site-packages/rest_framework/serializers.py", line 227, in is_valid
    self._validated_data = self.run_validation(self.initial_data)
                           ^^^^^^^^^^^^^^^^^^^^^^^^^^^^^^^^^^^^^^
  File "/home/kesley/Documents/house-management/backend/venv/lib/python3.11/site-packages/rest_framework/serializers.py", line 426, in run_validation
    value = self.to_internal_value(data)
            ^^^^^^^^^^^^^^^^^^^^^^^^^^^^
  File "/home/kesley/Documents/house-management/backend/finances/serializers.py", line 14, in to_internal_value
    subcategory = Subcategory.objects.get(name=data['subcategory'])
                  ^^^^^^^^^^^^^^^^^^^^^^^^^^^^^^^^^^^^^^^^^^^^^^^^^
  File "/home/kesley/Documents/house-management/backend/venv/lib/python3.11/site-packages/django/db/models/manager.py", line 87, in manager_method
    return getattr(self.get_queryset(), name)(*args, **kwargs)
           ^^^^^^^^^^^^^^^^^^^^^^^^^^^^^^^^^^^^^^^^^^^^^^^^^^^
  File "/home/kesley/Documents/house-management/backend/venv/lib/python3.11/site-packages/django/db/models/query.py", line 647, in get
    raise self.model.DoesNotExist(
finances.models.Subcategory.DoesNotExist: Subcategory matching query does not exist.
==================================================
Traceback:
2024-01-31 15:08:35.201050
Traceback (most recent call last):
  File "/home/kesley/Documents/house-management/backend/venv/lib/python3.11/site-packages/django/db/backends/utils.py", line 105, in _execute
    return self.cursor.execute(sql, params)
           ^^^^^^^^^^^^^^^^^^^^^^^^^^^^^^^^
psycopg2.errors.NumericValueOutOfRange: numeric field overflow
DETAIL:  A field with precision 10, scale 2 must round to an absolute value less than 10^8.


The above exception was the direct cause of the following exception:

Traceback (most recent call last):
  File "/home/kesley/Documents/house-management/backend/finances/views/CreateTransaction.py", line 29, in post
    payload = services.create_transaction()
              ^^^^^^^^^^^^^^^^^^^^^^^^^^^^^
  File "/home/kesley/Documents/house-management/backend/finances/services.py", line 58, in create_transaction
    Transaction.objects.create(description=description, value=value, category=category, subcategory=subcategory, date=date, created_by=created_by)
  File "/home/kesley/Documents/house-management/backend/venv/lib/python3.11/site-packages/django/db/models/manager.py", line 87, in manager_method
    return getattr(self.get_queryset(), name)(*args, **kwargs)
           ^^^^^^^^^^^^^^^^^^^^^^^^^^^^^^^^^^^^^^^^^^^^^^^^^^^
  File "/home/kesley/Documents/house-management/backend/venv/lib/python3.11/site-packages/django/db/models/query.py", line 677, in create
    obj.save(force_insert=True, using=self.db)
  File "/home/kesley/Documents/house-management/backend/venv/lib/python3.11/site-packages/django/db/models/base.py", line 814, in save
    self.save_base(
  File "/home/kesley/Documents/house-management/backend/venv/lib/python3.11/site-packages/django/db/models/base.py", line 901, in save_base
    updated = self._save_table(
              ^^^^^^^^^^^^^^^^^
  File "/home/kesley/Documents/house-management/backend/venv/lib/python3.11/site-packages/django/db/models/base.py", line 1059, in _save_table
    results = self._do_insert(
              ^^^^^^^^^^^^^^^^
  File "/home/kesley/Documents/house-management/backend/venv/lib/python3.11/site-packages/django/db/models/base.py", line 1100, in _do_insert
    return manager._insert(
           ^^^^^^^^^^^^^^^^
  File "/home/kesley/Documents/house-management/backend/venv/lib/python3.11/site-packages/django/db/models/manager.py", line 87, in manager_method
    return getattr(self.get_queryset(), name)(*args, **kwargs)
           ^^^^^^^^^^^^^^^^^^^^^^^^^^^^^^^^^^^^^^^^^^^^^^^^^^^
  File "/home/kesley/Documents/house-management/backend/venv/lib/python3.11/site-packages/django/db/models/query.py", line 1845, in _insert
    return query.get_compiler(using=using).execute_sql(returning_fields)
           ^^^^^^^^^^^^^^^^^^^^^^^^^^^^^^^^^^^^^^^^^^^^^^^^^^^^^^^^^^^^^
  File "/home/kesley/Documents/house-management/backend/venv/lib/python3.11/site-packages/django/db/models/sql/compiler.py", line 1822, in execute_sql
    cursor.execute(sql, params)
  File "/home/kesley/Documents/house-management/backend/venv/lib/python3.11/site-packages/django/db/backends/utils.py", line 122, in execute
    return super().execute(sql, params)
           ^^^^^^^^^^^^^^^^^^^^^^^^^^^^
  File "/home/kesley/Documents/house-management/backend/venv/lib/python3.11/site-packages/django/db/backends/utils.py", line 79, in execute
    return self._execute_with_wrappers(
           ^^^^^^^^^^^^^^^^^^^^^^^^^^^^
  File "/home/kesley/Documents/house-management/backend/venv/lib/python3.11/site-packages/django/db/backends/utils.py", line 92, in _execute_with_wrappers
    return executor(sql, params, many, context)
           ^^^^^^^^^^^^^^^^^^^^^^^^^^^^^^^^^^^^
  File "/home/kesley/Documents/house-management/backend/venv/lib/python3.11/site-packages/django/db/backends/utils.py", line 100, in _execute
    with self.db.wrap_database_errors:
  File "/home/kesley/Documents/house-management/backend/venv/lib/python3.11/site-packages/django/db/utils.py", line 91, in __exit__
    raise dj_exc_value.with_traceback(traceback) from exc_value
  File "/home/kesley/Documents/house-management/backend/venv/lib/python3.11/site-packages/django/db/backends/utils.py", line 105, in _execute
    return self.cursor.execute(sql, params)
           ^^^^^^^^^^^^^^^^^^^^^^^^^^^^^^^^
django.db.utils.DataError: numeric field overflow
DETAIL:  A field with precision 10, scale 2 must round to an absolute value less than 10^8.

==================================================
