Traceback:
2024-02-03 13:00:52.436678
Traceback (most recent call last):
  File "/home/kesley/Documents/house-management/backend/finances/views/CreateAccount.py", line 29, in post
    payload = services.create_account()
              ^^^^^^^^^^^^^^^^^^^^^^^^^
  File "/home/kesley/Documents/house-management/backend/finances/services.py", line 54, in create_account
    raise AccountAlreadyExists(self.messages.account_already_exists)
core.exceptions.AccountAlreadyExists: Account already exists.
==================================================
Traceback:
2024-02-03 13:04:04.885012
Traceback (most recent call last):
  File "/home/kesley/Documents/house-management/backend/finances/views/CreateTransaction.py", line 26, in post
    if not serializer.is_valid():
           ^^^^^^^^^^^^^^^^^^^^^
  File "/home/kesley/Documents/house-management/backend/venv/lib/python3.11/site-packages/rest_framework/serializers.py", line 227, in is_valid
    self._validated_data = self.run_validation(self.initial_data)
                           ^^^^^^^^^^^^^^^^^^^^^^^^^^^^^^^^^^^^^^
  File "/home/kesley/Documents/house-management/backend/venv/lib/python3.11/site-packages/rest_framework/serializers.py", line 426, in run_validation
    value = self.to_internal_value(data)
            ^^^^^^^^^^^^^^^^^^^^^^^^^^^^
  File "/home/kesley/Documents/house-management/backend/finances/serializers.py", line 16, in to_internal_value
    account = Account.objects.get(name=data['account'])
              ^^^^^^^^^^^^^^^^^^^^^^^^^^^^^^^^^^^^^^^^^
  File "/home/kesley/Documents/house-management/backend/venv/lib/python3.11/site-packages/django/db/models/manager.py", line 87, in manager_method
    return getattr(self.get_queryset(), name)(*args, **kwargs)
           ^^^^^^^^^^^^^^^^^^^^^^^^^^^^^^^^^^^^^^^^^^^^^^^^^^^
  File "/home/kesley/Documents/house-management/backend/venv/lib/python3.11/site-packages/django/db/models/query.py", line 647, in get
    raise self.model.DoesNotExist(
finances.models.Account.DoesNotExist: Account matching query does not exist.
==================================================
Traceback:
2024-02-03 13:30:06.303464
Traceback (most recent call last):
  File "/home/kesley/Documents/house-management/backend/finances/views/CreateAccount.py", line 29, in post
    payload = services.create_account()
              ^^^^^^^^^^^^^^^^^^^^^^^^^
  File "/home/kesley/Documents/house-management/backend/finances/services.py", line 54, in create_account
    raise AccountAlreadyExists(self.messages.account_already_exists)
core.exceptions.AccountAlreadyExists: Account already exists.
==================================================
