Traceback:
2024-02-16 13:39:41.209886
Traceback (most recent call last):
  File "/home/kesley/Documents/house-management/backend/venv/lib/python3.11/site-packages/django/db/backends/utils.py", line 105, in _execute
    return self.cursor.execute(sql, params)
           ^^^^^^^^^^^^^^^^^^^^^^^^^^^^^^^^
psycopg2.errors.UndefinedColumn: column finances_creditcardinstallment.installment_number does not exist
LINE 1: ...ue", "finances_creditcardinstallment"."due_date", "finances_...
                                                             ^


The above exception was the direct cause of the following exception:

Traceback (most recent call last):
  File "/home/kesley/Documents/house-management/backend/finances/views/GetCreditCardTransactions.py", line 27, in get
    'installments': [
                    ^
  File "/home/kesley/Documents/house-management/backend/venv/lib/python3.11/site-packages/django/db/models/query.py", line 398, in __iter__
    self._fetch_all()
  File "/home/kesley/Documents/house-management/backend/venv/lib/python3.11/site-packages/django/db/models/query.py", line 1926, in _fetch_all
    self._result_cache = list(self._iterable_class(self))
                         ^^^^^^^^^^^^^^^^^^^^^^^^^^^^^^^^
  File "/home/kesley/Documents/house-management/backend/venv/lib/python3.11/site-packages/django/db/models/query.py", line 91, in __iter__
    results = compiler.execute_sql(
              ^^^^^^^^^^^^^^^^^^^^^
  File "/home/kesley/Documents/house-management/backend/venv/lib/python3.11/site-packages/django/db/models/sql/compiler.py", line 1562, in execute_sql
    cursor.execute(sql, params)
  File "/home/kesley/Documents/house-management/backend/venv/lib/python3.11/site-packages/django/db/backends/utils.py", line 122, in execute
    return super().execute(sql, params)
           ^^^^^^^^^^^^^^^^^^^^^^^^^^^^
  File "/home/kesley/Documents/house-management/backend/venv/lib/python3.11/site-packages/django/db/backends/utils.py", line 79, in execute
    return self._execute_with_wrappers(
           ^^^^^^^^^^^^^^^^^^^^^^^^^^^^
  File "/home/kesley/Documents/house-management/backend/venv/lib/python3.11/site-packages/django/db/backends/utils.py", line 92, in _execute_with_wrappers
    return executor(sql, params, many, context)
           ^^^^^^^^^^^^^^^^^^^^^^^^^^^^^^^^^^^^
  File "/home/kesley/Documents/house-management/backend/venv/lib/python3.11/site-packages/django/db/backends/utils.py", line 100, in _execute
    with self.db.wrap_database_errors:
  File "/home/kesley/Documents/house-management/backend/venv/lib/python3.11/site-packages/django/db/utils.py", line 91, in __exit__
    raise dj_exc_value.with_traceback(traceback) from exc_value
  File "/home/kesley/Documents/house-management/backend/venv/lib/python3.11/site-packages/django/db/backends/utils.py", line 105, in _execute
    return self.cursor.execute(sql, params)
           ^^^^^^^^^^^^^^^^^^^^^^^^^^^^^^^^
django.db.utils.ProgrammingError: column finances_creditcardinstallment.installment_number does not exist
LINE 1: ...ue", "finances_creditcardinstallment"."due_date", "finances_...
                                                             ^

==================================================
Traceback:
2024-02-16 13:39:41.272251
Traceback (most recent call last):
  File "/home/kesley/Documents/house-management/backend/venv/lib/python3.11/site-packages/django/db/backends/utils.py", line 105, in _execute
    return self.cursor.execute(sql, params)
           ^^^^^^^^^^^^^^^^^^^^^^^^^^^^^^^^
psycopg2.errors.UndefinedColumn: column finances_creditcardinstallment.installment_number does not exist
LINE 1: ...ue", "finances_creditcardinstallment"."due_date", "finances_...
                                                             ^


The above exception was the direct cause of the following exception:

Traceback (most recent call last):
  File "/home/kesley/Documents/house-management/backend/finances/views/GetCreditCardTransactions.py", line 27, in get
    'installments': [
                    ^
  File "/home/kesley/Documents/house-management/backend/venv/lib/python3.11/site-packages/django/db/models/query.py", line 398, in __iter__
    self._fetch_all()
  File "/home/kesley/Documents/house-management/backend/venv/lib/python3.11/site-packages/django/db/models/query.py", line 1926, in _fetch_all
    self._result_cache = list(self._iterable_class(self))
                         ^^^^^^^^^^^^^^^^^^^^^^^^^^^^^^^^
  File "/home/kesley/Documents/house-management/backend/venv/lib/python3.11/site-packages/django/db/models/query.py", line 91, in __iter__
    results = compiler.execute_sql(
              ^^^^^^^^^^^^^^^^^^^^^
  File "/home/kesley/Documents/house-management/backend/venv/lib/python3.11/site-packages/django/db/models/sql/compiler.py", line 1562, in execute_sql
    cursor.execute(sql, params)
  File "/home/kesley/Documents/house-management/backend/venv/lib/python3.11/site-packages/django/db/backends/utils.py", line 122, in execute
    return super().execute(sql, params)
           ^^^^^^^^^^^^^^^^^^^^^^^^^^^^
  File "/home/kesley/Documents/house-management/backend/venv/lib/python3.11/site-packages/django/db/backends/utils.py", line 79, in execute
    return self._execute_with_wrappers(
           ^^^^^^^^^^^^^^^^^^^^^^^^^^^^
  File "/home/kesley/Documents/house-management/backend/venv/lib/python3.11/site-packages/django/db/backends/utils.py", line 92, in _execute_with_wrappers
    return executor(sql, params, many, context)
           ^^^^^^^^^^^^^^^^^^^^^^^^^^^^^^^^^^^^
  File "/home/kesley/Documents/house-management/backend/venv/lib/python3.11/site-packages/django/db/backends/utils.py", line 100, in _execute
    with self.db.wrap_database_errors:
  File "/home/kesley/Documents/house-management/backend/venv/lib/python3.11/site-packages/django/db/utils.py", line 91, in __exit__
    raise dj_exc_value.with_traceback(traceback) from exc_value
  File "/home/kesley/Documents/house-management/backend/venv/lib/python3.11/site-packages/django/db/backends/utils.py", line 105, in _execute
    return self.cursor.execute(sql, params)
           ^^^^^^^^^^^^^^^^^^^^^^^^^^^^^^^^
django.db.utils.ProgrammingError: column finances_creditcardinstallment.installment_number does not exist
LINE 1: ...ue", "finances_creditcardinstallment"."due_date", "finances_...
                                                             ^

==================================================
Traceback:
2024-02-16 13:40:15.454707
Traceback (most recent call last):
  File "/home/kesley/Documents/house-management/backend/venv/lib/python3.11/site-packages/django/db/backends/utils.py", line 105, in _execute
    return self.cursor.execute(sql, params)
           ^^^^^^^^^^^^^^^^^^^^^^^^^^^^^^^^
psycopg2.errors.UndefinedColumn: column finances_creditcardinstallment.installment_number does not exist
LINE 1: ...ue", "finances_creditcardinstallment"."due_date", "finances_...
                                                             ^


The above exception was the direct cause of the following exception:

Traceback (most recent call last):
  File "/home/kesley/Documents/house-management/backend/finances/views/GetCreditCardTransactions.py", line 27, in get
    'installments': [
                    ^
  File "/home/kesley/Documents/house-management/backend/venv/lib/python3.11/site-packages/django/db/models/query.py", line 398, in __iter__
    self._fetch_all()
  File "/home/kesley/Documents/house-management/backend/venv/lib/python3.11/site-packages/django/db/models/query.py", line 1926, in _fetch_all
    self._result_cache = list(self._iterable_class(self))
                         ^^^^^^^^^^^^^^^^^^^^^^^^^^^^^^^^
  File "/home/kesley/Documents/house-management/backend/venv/lib/python3.11/site-packages/django/db/models/query.py", line 91, in __iter__
    results = compiler.execute_sql(
              ^^^^^^^^^^^^^^^^^^^^^
  File "/home/kesley/Documents/house-management/backend/venv/lib/python3.11/site-packages/django/db/models/sql/compiler.py", line 1562, in execute_sql
    cursor.execute(sql, params)
  File "/home/kesley/Documents/house-management/backend/venv/lib/python3.11/site-packages/django/db/backends/utils.py", line 122, in execute
    return super().execute(sql, params)
           ^^^^^^^^^^^^^^^^^^^^^^^^^^^^
  File "/home/kesley/Documents/house-management/backend/venv/lib/python3.11/site-packages/django/db/backends/utils.py", line 79, in execute
    return self._execute_with_wrappers(
           ^^^^^^^^^^^^^^^^^^^^^^^^^^^^
  File "/home/kesley/Documents/house-management/backend/venv/lib/python3.11/site-packages/django/db/backends/utils.py", line 92, in _execute_with_wrappers
    return executor(sql, params, many, context)
           ^^^^^^^^^^^^^^^^^^^^^^^^^^^^^^^^^^^^
  File "/home/kesley/Documents/house-management/backend/venv/lib/python3.11/site-packages/django/db/backends/utils.py", line 100, in _execute
    with self.db.wrap_database_errors:
  File "/home/kesley/Documents/house-management/backend/venv/lib/python3.11/site-packages/django/db/utils.py", line 91, in __exit__
    raise dj_exc_value.with_traceback(traceback) from exc_value
  File "/home/kesley/Documents/house-management/backend/venv/lib/python3.11/site-packages/django/db/backends/utils.py", line 105, in _execute
    return self.cursor.execute(sql, params)
           ^^^^^^^^^^^^^^^^^^^^^^^^^^^^^^^^
django.db.utils.ProgrammingError: column finances_creditcardinstallment.installment_number does not exist
LINE 1: ...ue", "finances_creditcardinstallment"."due_date", "finances_...
                                                             ^

==================================================
Traceback:
2024-02-16 13:40:15.517199
Traceback (most recent call last):
  File "/home/kesley/Documents/house-management/backend/venv/lib/python3.11/site-packages/django/db/backends/utils.py", line 105, in _execute
    return self.cursor.execute(sql, params)
           ^^^^^^^^^^^^^^^^^^^^^^^^^^^^^^^^
psycopg2.errors.UndefinedColumn: column finances_creditcardinstallment.installment_number does not exist
LINE 1: ...ue", "finances_creditcardinstallment"."due_date", "finances_...
                                                             ^


The above exception was the direct cause of the following exception:

Traceback (most recent call last):
  File "/home/kesley/Documents/house-management/backend/finances/views/GetCreditCardTransactions.py", line 27, in get
    'installments': [
                    ^
  File "/home/kesley/Documents/house-management/backend/venv/lib/python3.11/site-packages/django/db/models/query.py", line 398, in __iter__
    self._fetch_all()
  File "/home/kesley/Documents/house-management/backend/venv/lib/python3.11/site-packages/django/db/models/query.py", line 1926, in _fetch_all
    self._result_cache = list(self._iterable_class(self))
                         ^^^^^^^^^^^^^^^^^^^^^^^^^^^^^^^^
  File "/home/kesley/Documents/house-management/backend/venv/lib/python3.11/site-packages/django/db/models/query.py", line 91, in __iter__
    results = compiler.execute_sql(
              ^^^^^^^^^^^^^^^^^^^^^
  File "/home/kesley/Documents/house-management/backend/venv/lib/python3.11/site-packages/django/db/models/sql/compiler.py", line 1562, in execute_sql
    cursor.execute(sql, params)
  File "/home/kesley/Documents/house-management/backend/venv/lib/python3.11/site-packages/django/db/backends/utils.py", line 122, in execute
    return super().execute(sql, params)
           ^^^^^^^^^^^^^^^^^^^^^^^^^^^^
  File "/home/kesley/Documents/house-management/backend/venv/lib/python3.11/site-packages/django/db/backends/utils.py", line 79, in execute
    return self._execute_with_wrappers(
           ^^^^^^^^^^^^^^^^^^^^^^^^^^^^
  File "/home/kesley/Documents/house-management/backend/venv/lib/python3.11/site-packages/django/db/backends/utils.py", line 92, in _execute_with_wrappers
    return executor(sql, params, many, context)
           ^^^^^^^^^^^^^^^^^^^^^^^^^^^^^^^^^^^^
  File "/home/kesley/Documents/house-management/backend/venv/lib/python3.11/site-packages/django/db/backends/utils.py", line 100, in _execute
    with self.db.wrap_database_errors:
  File "/home/kesley/Documents/house-management/backend/venv/lib/python3.11/site-packages/django/db/utils.py", line 91, in __exit__
    raise dj_exc_value.with_traceback(traceback) from exc_value
  File "/home/kesley/Documents/house-management/backend/venv/lib/python3.11/site-packages/django/db/backends/utils.py", line 105, in _execute
    return self.cursor.execute(sql, params)
           ^^^^^^^^^^^^^^^^^^^^^^^^^^^^^^^^
django.db.utils.ProgrammingError: column finances_creditcardinstallment.installment_number does not exist
LINE 1: ...ue", "finances_creditcardinstallment"."due_date", "finances_...
                                                             ^

==================================================
Traceback:
2024-02-16 14:04:33.413376
Traceback (most recent call last):
  File "/home/kesley/Documents/house-management/backend/finances/views/CreateTransaction.py", line 25, in post
    if not serializer.is_valid():
           ^^^^^^^^^^^^^^^^^^^^^
  File "/home/kesley/Documents/house-management/backend/venv/lib/python3.11/site-packages/rest_framework/serializers.py", line 227, in is_valid
    self._validated_data = self.run_validation(self.initial_data)
                           ^^^^^^^^^^^^^^^^^^^^^^^^^^^^^^^^^^^^^^
  File "/home/kesley/Documents/house-management/backend/venv/lib/python3.11/site-packages/rest_framework/serializers.py", line 426, in run_validation
    value = self.to_internal_value(data)
            ^^^^^^^^^^^^^^^^^^^^^^^^^^^^
  File "/home/kesley/Documents/house-management/backend/finances/serializers.py", line 17, in to_internal_value
    subcategory = Subcategory.objects.get(name=data['subcategory'])
                  ^^^^^^^^^^^^^^^^^^^^^^^^^^^^^^^^^^^^^^^^^^^^^^^^^
  File "/home/kesley/Documents/house-management/backend/venv/lib/python3.11/site-packages/django/db/models/manager.py", line 87, in manager_method
    return getattr(self.get_queryset(), name)(*args, **kwargs)
           ^^^^^^^^^^^^^^^^^^^^^^^^^^^^^^^^^^^^^^^^^^^^^^^^^^^
  File "/home/kesley/Documents/house-management/backend/venv/lib/python3.11/site-packages/django/db/models/query.py", line 647, in get
    raise self.model.DoesNotExist(
finances.models.Subcategory.DoesNotExist: Subcategory matching query does not exist.
==================================================
